<?xml version="1.0" encoding="UTF-8"?>
<testng-results skipped="0" failed="2" total="4" passed="2">
  <reporter-output>
    <line>
      <![CDATA[这是我写的日志]]>
    </line>
  </reporter-output>
  <suite name="测试套件" duration-ms="27" started-at="2022-03-14T10:10:14Z" finished-at="2022-03-14T10:10:14Z">
    <groups>
    </groups>
    <test name="一个测试模块" duration-ms="27" started-at="2022-03-14T10:10:14Z" finished-at="2022-03-14T10:10:14Z">
      <class name="com.tester.extend.demo.ReportTestDemo">
        <test-method status="FAIL" signature="test1()[pri:0, instance:com.tester.extend.demo.ReportTestDemo@35851384]" name="test1" duration-ms="9" started-at="2022-03-14T18:10:14Z" finished-at="2022-03-14T18:10:14Z">
          <exception class="java.lang.AssertionError">
            <message>
              <![CDATA[expected [2] but found [1]]]>
            </message>
            <full-stacktrace>
              <![CDATA[java.lang.AssertionError: expected [2] but found [1]
	at org.testng.Assert.fail(Assert.java:94)
	at org.testng.Assert.failNotEquals(Assert.java:496)
	at org.testng.Assert.assertEquals(Assert.java:125)
	at org.testng.Assert.assertEquals(Assert.java:372)
	at org.testng.Assert.assertEquals(Assert.java:382)
	at com.tester.extend.demo.ReportTestDemo.test1(ReportTestDemo.java:13)
	at sun.reflect.NativeMethodAccessorImpl.invoke0(Native Method)
	at sun.reflect.NativeMethodAccessorImpl.invoke(NativeMethodAccessorImpl.java:62)
	at sun.reflect.DelegatingMethodAccessorImpl.invoke(DelegatingMethodAccessorImpl.java:43)
	at java.lang.reflect.Method.invoke(Method.java:498)
	at org.testng.internal.MethodInvocationHelper.invokeMethod(MethodInvocationHelper.java:85)
	at org.testng.internal.Invoker.invokeMethod(Invoker.java:639)
	at org.testng.internal.Invoker.invokeTestMethod(Invoker.java:816)
	at org.testng.internal.Invoker.invokeTestMethods(Invoker.java:1124)
	at org.testng.internal.TestMethodWorker.invokeTestMethods(TestMethodWorker.java:125)
	at org.testng.internal.TestMethodWorker.run(TestMethodWorker.java:108)
	at org.testng.TestRunner.privateRun(TestRunner.java:774)
	at org.testng.TestRunner.run(TestRunner.java:624)
	at org.testng.SuiteRunner.runTest(SuiteRunner.java:359)
	at org.testng.SuiteRunner.runSequentially(SuiteRunner.java:354)
	at org.testng.SuiteRunner.privateRun(SuiteRunner.java:312)
	at org.testng.SuiteRunner.run(SuiteRunner.java:261)
	at org.testng.SuiteRunnerWorker.runSuite(SuiteRunnerWorker.java:52)
	at org.testng.SuiteRunnerWorker.run(SuiteRunnerWorker.java:86)
	at org.testng.TestNG.runSuitesSequentially(TestNG.java:1191)
	at org.testng.TestNG.runSuitesLocally(TestNG.java:1116)
	at org.testng.TestNG.run(TestNG.java:1024)
	at com.intellij.rt.testng.IDEARemoteTestNG.run(IDEARemoteTestNG.java:66)
	at com.intellij.rt.testng.RemoteTestNGStarter.main(RemoteTestNGStarter.java:110)
]]>
            </full-stacktrace>
          </exception> <!-- java.lang.AssertionError -->
          <reporter-output>
          </reporter-output>
        </test-method> <!-- test1 -->
        <test-method status="PASS" signature="test2()[pri:0, instance:com.tester.extend.demo.ReportTestDemo@35851384]" name="test2" duration-ms="0" started-at="2022-03-14T18:10:14Z" finished-at="2022-03-14T18:10:14Z">
          <reporter-output>
          </reporter-output>
        </test-method> <!-- test2 -->
        <test-method status="PASS" signature="test3()[pri:0, instance:com.tester.extend.demo.ReportTestDemo@35851384]" name="test3" duration-ms="0" started-at="2022-03-14T18:10:14Z" finished-at="2022-03-14T18:10:14Z">
          <reporter-output>
          </reporter-output>
        </test-method> <!-- test3 -->
        <test-method status="FAIL" signature="logDemo()[pri:0, instance:com.tester.extend.demo.ReportTestDemo@35851384]" name="logDemo" duration-ms="0" started-at="2022-03-14T18:10:14Z" finished-at="2022-03-14T18:10:14Z">
          <exception class="java.lang.RuntimeException">
            <message>
              <![CDATA[这是我自己运行时的异常]]>
            </message>
            <full-stacktrace>
              <![CDATA[java.lang.RuntimeException: 这是我自己运行时的异常
	at com.tester.extend.demo.ReportTestDemo.logDemo(ReportTestDemo.java:26)
	at sun.reflect.NativeMethodAccessorImpl.invoke0(Native Method)
	at sun.reflect.NativeMethodAccessorImpl.invoke(NativeMethodAccessorImpl.java:62)
	at sun.reflect.DelegatingMethodAccessorImpl.invoke(DelegatingMethodAccessorImpl.java:43)
	at java.lang.reflect.Method.invoke(Method.java:498)
	at org.testng.internal.MethodInvocationHelper.invokeMethod(MethodInvocationHelper.java:85)
	at org.testng.internal.Invoker.invokeMethod(Invoker.java:639)
	at org.testng.internal.Invoker.invokeTestMethod(Invoker.java:816)
	at org.testng.internal.Invoker.invokeTestMethods(Invoker.java:1124)
	at org.testng.internal.TestMethodWorker.invokeTestMethods(TestMethodWorker.java:125)
	at org.testng.internal.TestMethodWorker.run(TestMethodWorker.java:108)
	at org.testng.TestRunner.privateRun(TestRunner.java:774)
	at org.testng.TestRunner.run(TestRunner.java:624)
	at org.testng.SuiteRunner.runTest(SuiteRunner.java:359)
	at org.testng.SuiteRunner.runSequentially(SuiteRunner.java:354)
	at org.testng.SuiteRunner.privateRun(SuiteRunner.java:312)
	at org.testng.SuiteRunner.run(SuiteRunner.java:261)
	at org.testng.SuiteRunnerWorker.runSuite(SuiteRunnerWorker.java:52)
	at org.testng.SuiteRunnerWorker.run(SuiteRunnerWorker.java:86)
	at org.testng.TestNG.runSuitesSequentially(TestNG.java:1191)
	at org.testng.TestNG.runSuitesLocally(TestNG.java:1116)
	at org.testng.TestNG.run(TestNG.java:1024)
	at com.intellij.rt.testng.IDEARemoteTestNG.run(IDEARemoteTestNG.java:66)
	at com.intellij.rt.testng.RemoteTestNGStarter.main(RemoteTestNGStarter.java:110)
]]>
            </full-stacktrace>
          </exception> <!-- java.lang.RuntimeException -->
          <reporter-output>
            <line>
              <![CDATA[这是我写的日志]]>
            </line>
          </reporter-output>
        </test-method> <!-- logDemo -->
      </class> <!-- com.tester.extend.demo.ReportTestDemo -->
    </test> <!-- 一个测试模块 -->
  </suite> <!-- 测试套件 -->
</testng-results>
