<?xml version="1.0" encoding="UTF-8"?>
<!-- Generated by org.testng.reporters.JUnitXMLReporter -->
<testsuite hostname="IT-C02YW0R8LVDL.local" name="一个测试模块" tests="4" failures="2" timestamp="14 Mar 2022 10:10:14 GMT" time="0.027" errors="0">
  <testcase name="test1" time="0.009" classname="com.tester.extend.demo.ReportTestDemo">
    <failure type="java.lang.AssertionError" message="expected [2] but found [1]">
      <![CDATA[java.lang.AssertionError: expected [2] but found [1]
	at com.tester.extend.demo.ReportTestDemo.test1(ReportTestDemo.java:13)
	at com.intellij.rt.testng.IDEARemoteTestNG.run(IDEARemoteTestNG.java:66)
	at com.intellij.rt.testng.RemoteTestNGStarter.main(RemoteTestNGStarter.java:110)
... Removed 26 stack frames]]>
    </failure>
  </testcase> <!-- test1 -->
  <testcase name="test2" time="0.0" classname="com.tester.extend.demo.ReportTestDemo"/>
  <testcase name="test3" time="0.0" classname="com.tester.extend.demo.ReportTestDemo"/>
  <testcase name="logDemo" time="0.0" classname="com.tester.extend.demo.ReportTestDemo">
    <failure type="java.lang.RuntimeException" message="这是我自己运行时的异常">
      <![CDATA[java.lang.RuntimeException: 这是我自己运行时的异常
	at com.tester.extend.demo.ReportTestDemo.logDemo(ReportTestDemo.java:26)
	at com.intellij.rt.testng.IDEARemoteTestNG.run(IDEARemoteTestNG.java:66)
	at com.intellij.rt.testng.RemoteTestNGStarter.main(RemoteTestNGStarter.java:110)
... Removed 21 stack frames]]>
    </failure>
  </testcase> <!-- logDemo -->
</testsuite> <!-- 一个测试模块 -->
