<?xml version="1.0" encoding="UTF-8"?>
<!-- Generated by org.testng.reporters.JUnitReportReporter -->
<testsuite hostname="IT-C02YW0R8LVDL.local" name="com.tester.extend.demo.ReportTestDemo" tests="4" failures="1" timestamp="14 Mar 2022 10:10:15 GMT" time="0.009" errors="1">
  <testcase name="test2" time="0.000" classname="com.tester.extend.demo.ReportTestDemo"/>
  <testcase name="test3" time="0.000" classname="com.tester.extend.demo.ReportTestDemo"/>
  <testcase name="test1" time="0.009" classname="com.tester.extend.demo.ReportTestDemo">
    <failure type="java.lang.AssertionError" message="expected [2] but found [1]">
      <![CDATA[java.lang.AssertionError: expected [2] but found [1]
	at org.testng.Assert.fail(Assert.java:94)
	at org.testng.Assert.failNotEquals(Assert.java:496)
	at org.testng.Assert.assertEquals(Assert.java:125)
	at org.testng.Assert.assertEquals(Assert.java:372)
	at org.testng.Assert.assertEquals(Assert.java:382)
	at com.tester.extend.demo.ReportTestDemo.test1(ReportTestDemo.java:13)
	at sun.reflect.NativeMethodAccessorImpl.invoke0(Native Method)
	at sun.reflect.NativeMethodAccessorImpl.invoke(NativeMethodAccessorImpl.java:62)
	at sun.reflect.DelegatingMethodAccessorImpl.invoke(DelegatingMethodAccessorImpl.java:43)
	at java.lang.reflect.Method.invoke(Method.java:498)
	at org.testng.internal.MethodInvocationHelper.invokeMethod(MethodInvocationHelper.java:85)
	at org.testng.internal.Invoker.invokeMethod(Invoker.java:639)
	at org.testng.internal.Invoker.invokeTestMethod(Invoker.java:816)
	at org.testng.internal.Invoker.invokeTestMethods(Invoker.java:1124)
	at org.testng.internal.TestMethodWorker.invokeTestMethods(TestMethodWorker.java:125)
	at org.testng.internal.TestMethodWorker.run(TestMethodWorker.java:108)
	at org.testng.TestRunner.privateRun(TestRunner.java:774)
	at org.testng.TestRunner.run(TestRunner.java:624)
	at org.testng.SuiteRunner.runTest(SuiteRunner.java:359)
	at org.testng.SuiteRunner.runSequentially(SuiteRunner.java:354)
	at org.testng.SuiteRunner.privateRun(SuiteRunner.java:312)
	at org.testng.SuiteRunner.run(SuiteRunner.java:261)
	at org.testng.SuiteRunnerWorker.runSuite(SuiteRunnerWorker.java:52)
	at org.testng.SuiteRunnerWorker.run(SuiteRunnerWorker.java:86)
	at org.testng.TestNG.runSuitesSequentially(TestNG.java:1191)
	at org.testng.TestNG.runSuitesLocally(TestNG.java:1116)
	at org.testng.TestNG.run(TestNG.java:1024)
	at com.intellij.rt.testng.IDEARemoteTestNG.run(IDEARemoteTestNG.java:66)
	at com.intellij.rt.testng.RemoteTestNGStarter.main(RemoteTestNGStarter.java:110)
]]>
    </failure>
  </testcase> <!-- test1 -->
  <testcase name="logDemo" time="0.000" classname="com.tester.extend.demo.ReportTestDemo">
    <error type="java.lang.RuntimeException" message="这是我自己运行时的异常">
      <![CDATA[java.lang.RuntimeException: 这是我自己运行时的异常
	at com.tester.extend.demo.ReportTestDemo.logDemo(ReportTestDemo.java:26)
	at sun.reflect.NativeMethodAccessorImpl.invoke0(Native Method)
	at sun.reflect.NativeMethodAccessorImpl.invoke(NativeMethodAccessorImpl.java:62)
	at sun.reflect.DelegatingMethodAccessorImpl.invoke(DelegatingMethodAccessorImpl.java:43)
	at java.lang.reflect.Method.invoke(Method.java:498)
	at org.testng.internal.MethodInvocationHelper.invokeMethod(MethodInvocationHelper.java:85)
	at org.testng.internal.Invoker.invokeMethod(Invoker.java:639)
	at org.testng.internal.Invoker.invokeTestMethod(Invoker.java:816)
	at org.testng.internal.Invoker.invokeTestMethods(Invoker.java:1124)
	at org.testng.internal.TestMethodWorker.invokeTestMethods(TestMethodWorker.java:125)
	at org.testng.internal.TestMethodWorker.run(TestMethodWorker.java:108)
	at org.testng.TestRunner.privateRun(TestRunner.java:774)
	at org.testng.TestRunner.run(TestRunner.java:624)
	at org.testng.SuiteRunner.runTest(SuiteRunner.java:359)
	at org.testng.SuiteRunner.runSequentially(SuiteRunner.java:354)
	at org.testng.SuiteRunner.privateRun(SuiteRunner.java:312)
	at org.testng.SuiteRunner.run(SuiteRunner.java:261)
	at org.testng.SuiteRunnerWorker.runSuite(SuiteRunnerWorker.java:52)
	at org.testng.SuiteRunnerWorker.run(SuiteRunnerWorker.java:86)
	at org.testng.TestNG.runSuitesSequentially(TestNG.java:1191)
	at org.testng.TestNG.runSuitesLocally(TestNG.java:1116)
	at org.testng.TestNG.run(TestNG.java:1024)
	at com.intellij.rt.testng.IDEARemoteTestNG.run(IDEARemoteTestNG.java:66)
	at com.intellij.rt.testng.RemoteTestNGStarter.main(RemoteTestNGStarter.java:110)
]]>
    </error>
  </testcase> <!-- logDemo -->
</testsuite> <!-- com.tester.extend.demo.ReportTestDemo -->
